<?xml version="1.0" ?>
<!-- =================================================================================== -->
<!-- |    This document was autogenerated by xacro from gp7.urdf.xacro                 | -->
<!-- |    EDITING THIS FILE BY HAND IS NOT RECOMMENDED                                 | -->
<!-- |    This Yaskawa GP7 urdf file was generated using                               | -->
<!-- |    https://github.com/fizyr/yaskawa_gp7_support/tree/main?tab=readme-ov-file    | -->
<!-- |    and slightly modified.                                                       | -->
<!-- =================================================================================== -->
<robot name="gp7">
  <link name="Base">
    <visual>
      <geometry>
        <mesh filename="meshes/visual/gp7_base_axis.stl"/>
      </geometry>
      <material name="blue">
        <color rgba="0 0 1 1"/>
      </material>
    </visual>
    <collision>
      <geometry>
        <mesh filename="meshes/collision/gp7_base_axis.stl"/>
      </geometry>
      <material name="yellow">
        <color rgba="0 1 1 1"/>
      </material>
    </collision>
  </link>
  <link name="vendor_base_link"/>
  <link name="Link1">
    <visual>
      <geometry>
        <mesh filename="meshes/visual/gp7_s_axis.stl"/>
      </geometry>
      <material name="silver">
        <color rgba="0.8 0.8 0.8 1"/>
      </material>
    </visual>
    <collision>
      <geometry>
        <mesh filename="meshes/collision/gp7_s_axis.stl"/>
      </geometry>
      <material name="yellow"/>
    </collision>
  </link>
  <link name="Link2">
    <visual>
      <geometry>
        <mesh filename="meshes/visual/gp7_l_axis.stl"/>
      </geometry>
      <material name="blue">
        <color rgba="0 0 1 1"/>
      </material>
    </visual>
    <collision>
      <geometry>
        <mesh filename="meshes/collision/gp7_l_axis.stl"/>
      </geometry>
      <material name="yellow"/>
    </collision>
  </link>
  <link name="Link3">
    <visual>
      <geometry>
        <mesh filename="meshes/visual/gp7_u_axis.stl"/>
      </geometry>
      <material name="silver">
        <color rgba="0.8 0.8 0.8 1"/>
      </material>
    </visual>
    <collision>
      <geometry>
        <mesh filename="meshes/collision/gp7_u_axis.stl"/>
      </geometry>
      <material name="yellow"/>
    </collision>
  </link>
  <link name="Link4">
    <visual>
      <geometry>
        <mesh filename="meshes/visual/gp7_r_axis.stl"/>
      </geometry>
      <material name="blue">
        <color rgba="0 0 1 1"/>
      </material>
    </visual>
    <collision>
      <geometry>
        <mesh filename="meshes/collision/gp7_r_axis.stl"/>
      </geometry>
      <material name="yellow"/>
    </collision>
  </link>
  <link name="Link5">
    <visual>
      <geometry>
        <mesh filename="meshes/visual/gp7_b_axis.stl"/>
      </geometry>
      <material name="silver">
        <color rgba="0.8 0.8 0.8 1"/>
      </material>
    </visual>
    <collision>
      <geometry>
        <mesh filename="meshes/collision/gp7_b_axis.stl"/>
      </geometry>
      <material name="yellow"/>
    </collision>
  </link>
  <link name="Link6">
    <visual>
      <geometry>
        <mesh filename="meshes/visual/gp7_t_axis.stl"/>
      </geometry>
      <material name="blue">
        <color rgba="0 0 1 1"/>
      </material>
    </visual>
    <collision>
      <geometry>
        <mesh filename="meshes/collision/gp7_t_axis.stl"/>
      </geometry>
      <material name="yellow"/>
    </collision>
  </link>
  <link name="flange"/>
  <link name="torch">
    <visual>
      <geometry>
        <!-- <mesh filename="file:${mesh_path}/visual/torch_visual.stl" /> -->
        <mesh filename="meshes/visual/torch_visual_shortened_head.stl"/>
      </geometry>
      <material name="silver">
        <color rgba="0.8 0.8 0.8 1"/>
      </material>
    </visual>
    <collision>
      <geometry>
        <!-- <mesh filename="file:${mesh_path}/collision/torch_collision.stl" /> -->
        <mesh filename="meshes/collision/torch_collision_shortened_head.stl"/>
      </geometry>
      <material name="yellow">
        <color rgba="0 1 1 1"/>
      </material>
    </collision>
  </link>
  <link name="tool_center_point"/>
  <!-- joint list -->
  <joint name="RevoluteJoint1" type="revolute">
    <parent link="Base"/>
    <child link="Link1"/>
    <origin xyz="0 0 0"/>
    <axis xyz="0 0 1"/>
    <limit effort="1" lower="-2.96705961" upper="2.96705961" velocity="6.544984694978735"/>
  </joint>
  <joint name="joint_vendor_base" type="fixed">
    <parent link="Base"/>
    <child link="vendor_base_link"/>
    <origin xyz="0 0 0.330"/>
  </joint>
  <joint name="RevoluteJoint2" type="revolute">
    <parent link="Link1"/>
    <child link="Link2"/>
    <origin xyz="0.040 0 0.330"/>
    <axis xyz="0 1 0"/>
    <limit effort="1" lower="-2.53072739" upper="1.13446403" velocity="5.497787143782138"/>
  </joint>
  <joint name="RevoluteJoint3" type="revolute">
    <parent link="Link2"/>
    <child link="Link3"/>
    <origin xyz="0 0 0.445"/>
    <axis xyz="0 -1 0"/>
    <limit effort="1" lower="-1.22173047" upper="3.31612563" velocity="7.155849933176751"/>
  </joint>
  <joint name="RevoluteJoint4" type="revolute">
    <parent link="Link3"/>
    <child link="Link4"/>
    <origin xyz="0.0 0 0.040"/>
    <axis xyz="-1 0 0"/>
    <limit effort="1" lower="-3.31612563" upper="3.31612563" velocity="9.599310885968812"/>
  </joint>
  <joint name="RevoluteJoint5" type="revolute">
    <parent link="Link4"/>
    <child link="Link5"/>
    <origin xyz="0.440 0 0"/>
    <axis xyz="0 -1 0"/>
    <limit effort="1" lower="-2.3561945" upper="2.3561945" velocity="9.599310885968812"/>
  </joint>
  <joint name="RevoluteJoint6" type="revolute">
    <parent link="Link5"/>
    <child link="Link6"/>
    <origin xyz="0.080 0 0"/>
    <axis xyz="-1 0 0"/>
    <limit effort="1" lower="-6.28318548" upper="6.28318548" velocity="17.453292519943293"/>
  </joint>
  <joint name="FixedJoint1" type="fixed">
    <parent link="Link6"/>
    <child link="flange"/>
    <origin rpy="0 -1.5707963267948966 3.141592653589793"/>
  </joint>
  <joint name="TorchJoint" type="fixed">
    <parent link="flange"/>
    <child link="torch"/>
    <origin rpy="0 0 -1.5707963267948966" xyz="0 0 -0.015262616184248623"/>
  </joint>
  <joint name="FixedJoint2" type="fixed">
    <parent link="torch"/>
    <child link="tool_center_point"/>
    <origin rpy="0.349066 0 0" xyz="0 0.0495 0.398"/>
  </joint>
</robot>
